Traceback (most recent call last):
  File "/opt/conda/envs/rtraining/lib/python3.8/site-packages/jupyter_cache/executors/utils.py", line 58, in single_nb_execution
    executenb(
  File "/opt/conda/envs/rtraining/lib/python3.8/site-packages/nbclient/client.py", line 1305, in execute
    return NotebookClient(nb=nb, resources=resources, km=km, **kwargs).execute()
  File "/opt/conda/envs/rtraining/lib/python3.8/site-packages/jupyter_core/utils/__init__.py", line 166, in wrapped
    return loop.run_until_complete(inner)
  File "/opt/conda/envs/rtraining/lib/python3.8/asyncio/base_events.py", line 616, in run_until_complete
    return future.result()
  File "/opt/conda/envs/rtraining/lib/python3.8/site-packages/nbclient/client.py", line 705, in async_execute
    await self.async_execute_cell(
  File "/opt/conda/envs/rtraining/lib/python3.8/site-packages/nbclient/client.py", line 1058, in async_execute_cell
    await self._check_raise_for_error(cell, cell_index, exec_reply)
  File "/opt/conda/envs/rtraining/lib/python3.8/site-packages/nbclient/client.py", line 914, in _check_raise_for_error
    raise CellExecutionError.from_cell_and_msg(cell, exec_reply_content)
nbclient.exceptions.CellExecutionError: An error occurred while executing the following cell:
------------------
#a)
schüler_1 <- factor(c("Anton", "Luca", "Matteo", "Max", "Emil"), ordered = TRUE)

#b)
schüler[4]

#c)
schüler_2 <- factor(schüler_1, ordered=TRUE, levels=c("Anton", "Luca", "Matteo", "Max", "Emil"))

#d)
print(schüler_1) #alternativ auch ohne "print()"
print(schüler_2) #alternativ auch ohne "print()"
------------------


Error in eval(expr, envir, enclos): object 'schüler' not found
Traceback:


